Failure # 1 (occurred at 2024-06-06_09-03-20)
[36mray::PPO.train()[39m (pid=26952, ip=127.0.0.1, actor_id=56c0535631ab85ed3810575401000000, repr=PPO)
  File "python\ray\_raylet.pyx", line 1887, in ray._raylet.execute_task
  File "python\ray\_raylet.pyx", line 1828, in ray._raylet.execute_task.function_executor
  File "c:\Users\p.archipczuk\AppData\Local\anaconda3\envs\RL\Lib\site-packages\ray\_private\function_manager.py", line 691, in actor_method_executor
    return method(__ray_actor, *args, **kwargs)
           ^^^^^^^^^^^^^^^^^^^^^^^^^^^^^^^^^^^^
  File "c:\Users\p.archipczuk\AppData\Local\anaconda3\envs\RL\Lib\site-packages\ray\util\tracing\tracing_helper.py", line 467, in _resume_span
    return method(self, *_args, **_kwargs)
           ^^^^^^^^^^^^^^^^^^^^^^^^^^^^^^^
  File "c:\Users\p.archipczuk\AppData\Local\anaconda3\envs\RL\Lib\site-packages\ray\tune\trainable\trainable.py", line 331, in train
    raise skipped from exception_cause(skipped)
  File "c:\Users\p.archipczuk\AppData\Local\anaconda3\envs\RL\Lib\site-packages\ray\tune\trainable\trainable.py", line 328, in train
    result = self.step()
             ^^^^^^^^^^^
  File "c:\Users\p.archipczuk\AppData\Local\anaconda3\envs\RL\Lib\site-packages\ray\util\tracing\tracing_helper.py", line 467, in _resume_span
    return method(self, *_args, **_kwargs)
           ^^^^^^^^^^^^^^^^^^^^^^^^^^^^^^^
  File "c:\Users\p.archipczuk\AppData\Local\anaconda3\envs\RL\Lib\site-packages\ray\rllib\algorithms\algorithm.py", line 878, in step
    train_results, train_iter_ctx = self._run_one_training_iteration()
                                    ^^^^^^^^^^^^^^^^^^^^^^^^^^^^^^^^^^
  File "c:\Users\p.archipczuk\AppData\Local\anaconda3\envs\RL\Lib\site-packages\ray\util\tracing\tracing_helper.py", line 467, in _resume_span
    return method(self, *_args, **_kwargs)
           ^^^^^^^^^^^^^^^^^^^^^^^^^^^^^^^
  File "c:\Users\p.archipczuk\AppData\Local\anaconda3\envs\RL\Lib\site-packages\ray\rllib\algorithms\algorithm.py", line 3156, in _run_one_training_iteration
    results = self.training_step()
              ^^^^^^^^^^^^^^^^^^^^
  File "c:\Users\p.archipczuk\AppData\Local\anaconda3\envs\RL\Lib\site-packages\ray\util\tracing\tracing_helper.py", line 467, in _resume_span
    return method(self, *_args, **_kwargs)
           ^^^^^^^^^^^^^^^^^^^^^^^^^^^^^^^
  File "c:\Users\p.archipczuk\AppData\Local\anaconda3\envs\RL\Lib\site-packages\ray\rllib\algorithms\ppo\ppo.py", line 426, in training_step
    return self._training_step_old_and_hybrid_api_stacks()
           ^^^^^^^^^^^^^^^^^^^^^^^^^^^^^^^^^^^^^^^^^^^^^^^
  File "c:\Users\p.archipczuk\AppData\Local\anaconda3\envs\RL\Lib\site-packages\ray\util\tracing\tracing_helper.py", line 467, in _resume_span
    return method(self, *_args, **_kwargs)
           ^^^^^^^^^^^^^^^^^^^^^^^^^^^^^^^
  File "c:\Users\p.archipczuk\AppData\Local\anaconda3\envs\RL\Lib\site-packages\ray\rllib\algorithms\ppo\ppo.py", line 576, in _training_step_old_and_hybrid_api_stacks
    train_batch = synchronous_parallel_sample(
                  ^^^^^^^^^^^^^^^^^^^^^^^^^^^^
  File "c:\Users\p.archipczuk\AppData\Local\anaconda3\envs\RL\Lib\site-packages\ray\rllib\execution\rollout_ops.py", line 97, in synchronous_parallel_sample
    sampled_data = worker_set.foreach_worker(
                   ^^^^^^^^^^^^^^^^^^^^^^^^^^
  File "c:\Users\p.archipczuk\AppData\Local\anaconda3\envs\RL\Lib\site-packages\ray\rllib\evaluation\worker_set.py", line 831, in foreach_worker
    handle_remote_call_result_errors(
  File "c:\Users\p.archipczuk\AppData\Local\anaconda3\envs\RL\Lib\site-packages\ray\rllib\evaluation\worker_set.py", line 80, in handle_remote_call_result_errors
    raise r.get()
ray.exceptions.RayTaskError(ValueError): [36mray::RolloutWorker.apply()[39m (pid=17732, ip=127.0.0.1, actor_id=5ed39a6530127b1bd2de648e01000000, repr=<ray.rllib.evaluation.rollout_worker.RolloutWorker object at 0x000001A30BF98410>)
  File "python\ray\_raylet.pyx", line 1887, in ray._raylet.execute_task
  File "python\ray\_raylet.pyx", line 1828, in ray._raylet.execute_task.function_executor
  File "c:\Users\p.archipczuk\AppData\Local\anaconda3\envs\RL\Lib\site-packages\ray\_private\function_manager.py", line 691, in actor_method_executor
    return method(__ray_actor, *args, **kwargs)
           ^^^^^^^^^^^^^^^^^^^^^^^^^^^^^^^^^^^^
  File "c:\Users\p.archipczuk\AppData\Local\anaconda3\envs\RL\Lib\site-packages\ray\util\tracing\tracing_helper.py", line 467, in _resume_span
    return method(self, *_args, **_kwargs)
           ^^^^^^^^^^^^^^^^^^^^^^^^^^^^^^^
  File "c:\Users\p.archipczuk\AppData\Local\anaconda3\envs\RL\Lib\site-packages\ray\rllib\utils\actor_manager.py", line 189, in apply
    raise e
  File "c:\Users\p.archipczuk\AppData\Local\anaconda3\envs\RL\Lib\site-packages\ray\rllib\utils\actor_manager.py", line 178, in apply
    return func(self, *args, **kwargs)
           ^^^^^^^^^^^^^^^^^^^^^^^^^^^
  File "c:\Users\p.archipczuk\AppData\Local\anaconda3\envs\RL\Lib\site-packages\ray\rllib\execution\rollout_ops.py", line 99, in <lambda>
    (lambda w: w.sample())
               ^^^^^^^^^^
  File "c:\Users\p.archipczuk\AppData\Local\anaconda3\envs\RL\Lib\site-packages\ray\util\tracing\tracing_helper.py", line 467, in _resume_span
    return method(self, *_args, **_kwargs)
           ^^^^^^^^^^^^^^^^^^^^^^^^^^^^^^^
  File "c:\Users\p.archipczuk\AppData\Local\anaconda3\envs\RL\Lib\site-packages\ray\rllib\evaluation\rollout_worker.py", line 685, in sample
    batches = [self.input_reader.next()]
               ^^^^^^^^^^^^^^^^^^^^^^^^
  File "c:\Users\p.archipczuk\AppData\Local\anaconda3\envs\RL\Lib\site-packages\ray\rllib\evaluation\sampler.py", line 91, in next
    batches = [self.get_data()]
               ^^^^^^^^^^^^^^^
  File "c:\Users\p.archipczuk\AppData\Local\anaconda3\envs\RL\Lib\site-packages\ray\rllib\evaluation\sampler.py", line 273, in get_data
    item = next(self._env_runner)
           ^^^^^^^^^^^^^^^^^^^^^^
  File "c:\Users\p.archipczuk\AppData\Local\anaconda3\envs\RL\Lib\site-packages\ray\rllib\evaluation\env_runner_v2.py", line 348, in run
    outputs = self.step()
              ^^^^^^^^^^^
  File "c:\Users\p.archipczuk\AppData\Local\anaconda3\envs\RL\Lib\site-packages\ray\rllib\evaluation\env_runner_v2.py", line 386, in step
    eval_results = self._do_policy_eval(to_eval=to_eval)
                   ^^^^^^^^^^^^^^^^^^^^^^^^^^^^^^^^^^^^^
  File "c:\Users\p.archipczuk\AppData\Local\anaconda3\envs\RL\Lib\site-packages\ray\rllib\evaluation\env_runner_v2.py", line 1086, in _do_policy_eval
    eval_results[policy_id] = policy.compute_actions_from_input_dict(
                              ^^^^^^^^^^^^^^^^^^^^^^^^^^^^^^^^^^^^^^^
  File "c:\Users\p.archipczuk\AppData\Local\anaconda3\envs\RL\Lib\site-packages\ray\rllib\policy\torch_policy_v2.py", line 557, in compute_actions_from_input_dict
    return self._compute_action_helper(
           ^^^^^^^^^^^^^^^^^^^^^^^^^^^^
  File "c:\Users\p.archipczuk\AppData\Local\anaconda3\envs\RL\Lib\site-packages\ray\rllib\utils\threading.py", line 24, in wrapper
    return func(self, *a, **k)
           ^^^^^^^^^^^^^^^^^^^
  File "c:\Users\p.archipczuk\AppData\Local\anaconda3\envs\RL\Lib\site-packages\ray\rllib\policy\torch_policy_v2.py", line 1272, in _compute_action_helper
    action_dist = dist_class(dist_inputs, self.model)
                  ^^^^^^^^^^^^^^^^^^^^^^^^^^^^^^^^^^^
  File "c:\Users\p.archipczuk\AppData\Local\anaconda3\envs\RL\Lib\site-packages\ray\rllib\models\torch\torch_action_dist.py", line 73, in __init__
    self.dist = torch.distributions.categorical.Categorical(logits=self.inputs)
                ^^^^^^^^^^^^^^^^^^^^^^^^^^^^^^^^^^^^^^^^^^^^^^^^^^^^^^^^^^^^^^^
  File "c:\Users\p.archipczuk\AppData\Local\anaconda3\envs\RL\Lib\site-packages\torch\distributions\categorical.py", line 70, in __init__
    super().__init__(batch_shape, validate_args=validate_args)
  File "c:\Users\p.archipczuk\AppData\Local\anaconda3\envs\RL\Lib\site-packages\torch\distributions\distribution.py", line 68, in __init__
    raise ValueError(
ValueError: Expected parameter logits (Tensor of shape (8, 3)) of distribution Categorical(logits: torch.Size([8, 3])) to satisfy the constraint IndependentConstraint(Real(), 1), but found invalid values:
tensor([[-1.0920, -1.1030, -1.1010],
        [-1.0919, -1.1045, -1.0994],
        [-1.0911, -1.1043, -1.1005],
        [-1.0919, -1.1030, -1.1009],
        [-1.0920, -1.1044, -1.0995],
        [-1.0919, -1.1047, -1.0993],
        [-1.0919, -1.1030, -1.1009],
        [    nan,     nan,     nan]])
