Failure # 1 (occurred at 2024-06-06_09-51-01)
[36mray::PPO.train()[39m (pid=33028, ip=127.0.0.1, actor_id=4c73366e7fd2bfb440478cf001000000, repr=PPO)
  File "python\ray\_raylet.pyx", line 1887, in ray._raylet.execute_task
  File "python\ray\_raylet.pyx", line 1828, in ray._raylet.execute_task.function_executor
  File "c:\Users\p.archipczuk\AppData\Local\anaconda3\envs\RL\Lib\site-packages\ray\_private\function_manager.py", line 691, in actor_method_executor
    return method(__ray_actor, *args, **kwargs)
           ^^^^^^^^^^^^^^^^^^^^^^^^^^^^^^^^^^^^
  File "c:\Users\p.archipczuk\AppData\Local\anaconda3\envs\RL\Lib\site-packages\ray\util\tracing\tracing_helper.py", line 467, in _resume_span
    return method(self, *_args, **_kwargs)
           ^^^^^^^^^^^^^^^^^^^^^^^^^^^^^^^
  File "c:\Users\p.archipczuk\AppData\Local\anaconda3\envs\RL\Lib\site-packages\ray\tune\trainable\trainable.py", line 331, in train
    raise skipped from exception_cause(skipped)
  File "c:\Users\p.archipczuk\AppData\Local\anaconda3\envs\RL\Lib\site-packages\ray\tune\trainable\trainable.py", line 328, in train
    result = self.step()
             ^^^^^^^^^^^
  File "c:\Users\p.archipczuk\AppData\Local\anaconda3\envs\RL\Lib\site-packages\ray\util\tracing\tracing_helper.py", line 467, in _resume_span
    return method(self, *_args, **_kwargs)
           ^^^^^^^^^^^^^^^^^^^^^^^^^^^^^^^
  File "c:\Users\p.archipczuk\AppData\Local\anaconda3\envs\RL\Lib\site-packages\ray\rllib\algorithms\algorithm.py", line 878, in step
    train_results, train_iter_ctx = self._run_one_training_iteration()
                                    ^^^^^^^^^^^^^^^^^^^^^^^^^^^^^^^^^^
  File "c:\Users\p.archipczuk\AppData\Local\anaconda3\envs\RL\Lib\site-packages\ray\util\tracing\tracing_helper.py", line 467, in _resume_span
    return method(self, *_args, **_kwargs)
           ^^^^^^^^^^^^^^^^^^^^^^^^^^^^^^^
  File "c:\Users\p.archipczuk\AppData\Local\anaconda3\envs\RL\Lib\site-packages\ray\rllib\algorithms\algorithm.py", line 3156, in _run_one_training_iteration
    results = self.training_step()
              ^^^^^^^^^^^^^^^^^^^^
  File "c:\Users\p.archipczuk\AppData\Local\anaconda3\envs\RL\Lib\site-packages\ray\util\tracing\tracing_helper.py", line 467, in _resume_span
    return method(self, *_args, **_kwargs)
           ^^^^^^^^^^^^^^^^^^^^^^^^^^^^^^^
  File "c:\Users\p.archipczuk\AppData\Local\anaconda3\envs\RL\Lib\site-packages\ray\rllib\algorithms\ppo\ppo.py", line 426, in training_step
    return self._training_step_old_and_hybrid_api_stacks()
           ^^^^^^^^^^^^^^^^^^^^^^^^^^^^^^^^^^^^^^^^^^^^^^^
  File "c:\Users\p.archipczuk\AppData\Local\anaconda3\envs\RL\Lib\site-packages\ray\util\tracing\tracing_helper.py", line 467, in _resume_span
    return method(self, *_args, **_kwargs)
           ^^^^^^^^^^^^^^^^^^^^^^^^^^^^^^^
  File "c:\Users\p.archipczuk\AppData\Local\anaconda3\envs\RL\Lib\site-packages\ray\rllib\algorithms\ppo\ppo.py", line 576, in _training_step_old_and_hybrid_api_stacks
    train_batch = synchronous_parallel_sample(
                  ^^^^^^^^^^^^^^^^^^^^^^^^^^^^
  File "c:\Users\p.archipczuk\AppData\Local\anaconda3\envs\RL\Lib\site-packages\ray\rllib\execution\rollout_ops.py", line 97, in synchronous_parallel_sample
    sampled_data = worker_set.foreach_worker(
                   ^^^^^^^^^^^^^^^^^^^^^^^^^^
  File "c:\Users\p.archipczuk\AppData\Local\anaconda3\envs\RL\Lib\site-packages\ray\rllib\evaluation\worker_set.py", line 831, in foreach_worker
    handle_remote_call_result_errors(
  File "c:\Users\p.archipczuk\AppData\Local\anaconda3\envs\RL\Lib\site-packages\ray\rllib\evaluation\worker_set.py", line 80, in handle_remote_call_result_errors
    raise r.get()
  File "c:\Users\p.archipczuk\AppData\Local\anaconda3\envs\RL\Lib\site-packages\ray\rllib\utils\actor_manager.py", line 497, in _fetch_result
    result = ray.get(r)
             ^^^^^^^^^^
  File "c:\Users\p.archipczuk\AppData\Local\anaconda3\envs\RL\Lib\site-packages\ray\_private\auto_init_hook.py", line 21, in auto_init_wrapper
    return fn(*args, **kwargs)
           ^^^^^^^^^^^^^^^^^^^
  File "c:\Users\p.archipczuk\AppData\Local\anaconda3\envs\RL\Lib\site-packages\ray\_private\client_mode_hook.py", line 103, in wrapper
    return func(*args, **kwargs)
           ^^^^^^^^^^^^^^^^^^^^^
  File "c:\Users\p.archipczuk\AppData\Local\anaconda3\envs\RL\Lib\site-packages\ray\_private\worker.py", line 2623, in get
    values, debugger_breakpoint = worker.get_objects(object_refs, timeout=timeout)
                                  ^^^^^^^^^^^^^^^^^^^^^^^^^^^^^^^^^^^^^^^^^^^^^^^^
  File "c:\Users\p.archipczuk\AppData\Local\anaconda3\envs\RL\Lib\site-packages\ray\_private\worker.py", line 861, in get_objects
    raise value.as_instanceof_cause()
ray.exceptions.RayTaskError: [36mray::RolloutWorker.apply()[39m (pid=4628, ip=127.0.0.1, actor_id=831e634e44dbfc65fc89c29901000000, repr=<ray.rllib.evaluation.rollout_worker.RolloutWorker object at 0x000002095D964E90>)
  File "python\ray\_raylet.pyx", line 1887, in ray._raylet.execute_task
  File "python\ray\_raylet.pyx", line 1828, in ray._raylet.execute_task.function_executor
  File "c:\Users\p.archipczuk\AppData\Local\anaconda3\envs\RL\Lib\site-packages\ray\_private\function_manager.py", line 691, in actor_method_executor
    return method(__ray_actor, *args, **kwargs)
           ^^^^^^^^^^^^^^^^^^^^^^^^^^^^^^^^^^^^
  File "c:\Users\p.archipczuk\AppData\Local\anaconda3\envs\RL\Lib\site-packages\ray\util\tracing\tracing_helper.py", line 467, in _resume_span
    return method(self, *_args, **_kwargs)
           ^^^^^^^^^^^^^^^^^^^^^^^^^^^^^^^
  File "c:\Users\p.archipczuk\AppData\Local\anaconda3\envs\RL\Lib\site-packages\ray\rllib\utils\actor_manager.py", line 189, in apply
    raise e
  File "c:\Users\p.archipczuk\AppData\Local\anaconda3\envs\RL\Lib\site-packages\ray\rllib\utils\actor_manager.py", line 178, in apply
    return func(self, *args, **kwargs)
           ^^^^^^^^^^^^^^^^^^^^^^^^^^^
  File "c:\Users\p.archipczuk\AppData\Local\anaconda3\envs\RL\Lib\site-packages\ray\rllib\execution\rollout_ops.py", line 99, in <lambda>
    (lambda w: w.sample())
               ^^^^^^^^^^
  File "c:\Users\p.archipczuk\AppData\Local\anaconda3\envs\RL\Lib\site-packages\ray\util\tracing\tracing_helper.py", line 467, in _resume_span
    return method(self, *_args, **_kwargs)
           ^^^^^^^^^^^^^^^^^^^^^^^^^^^^^^^
  File "c:\Users\p.archipczuk\AppData\Local\anaconda3\envs\RL\Lib\site-packages\ray\rllib\evaluation\rollout_worker.py", line 685, in sample
    batches = [self.input_reader.next()]
               ^^^^^^^^^^^^^^^^^^^^^^^^
  File "c:\Users\p.archipczuk\AppData\Local\anaconda3\envs\RL\Lib\site-packages\ray\rllib\evaluation\sampler.py", line 91, in next
    batches = [self.get_data()]
               ^^^^^^^^^^^^^^^
  File "c:\Users\p.archipczuk\AppData\Local\anaconda3\envs\RL\Lib\site-packages\ray\rllib\evaluation\sampler.py", line 273, in get_data
    item = next(self._env_runner)
           ^^^^^^^^^^^^^^^^^^^^^^
  File "c:\Users\p.archipczuk\AppData\Local\anaconda3\envs\RL\Lib\site-packages\ray\rllib\evaluation\env_runner_v2.py", line 348, in run
    outputs = self.step()
              ^^^^^^^^^^^
  File "c:\Users\p.archipczuk\AppData\Local\anaconda3\envs\RL\Lib\site-packages\ray\rllib\evaluation\env_runner_v2.py", line 404, in step
    self._base_env.send_actions(actions_to_send)
  File "c:\Users\p.archipczuk\AppData\Local\anaconda3\envs\RL\Lib\site-packages\ray\rllib\env\multi_agent_env.py", line 647, in send_actions
    raise e
  File "c:\Users\p.archipczuk\AppData\Local\anaconda3\envs\RL\Lib\site-packages\ray\rllib\env\multi_agent_env.py", line 636, in send_actions
    obs, rewards, terminateds, truncateds, infos = env.step(agent_dict)
                                                   ^^^^^^^^^^^^^^^^^^^^
  File "c:\Users\p.archipczuk\AppData\Local\anaconda3\envs\RL\Lib\site-packages\ray\rllib\env\wrappers\pettingzoo_env.py", line 218, in step
    obss, rews, terminateds, truncateds, infos = self.par_env.step(action_dict)
                                                 ^^^^^^^^^^^^^^^^^^^^^^^^^^^^^^
  File "d:\mesdocuments\paul\gertrude\travail\R&D\projets\generation_diag\travail\src\FpfEnv_v2.py", line 220, in step
    observations = self._compute_observations()
                   ^^^^^^^^^^^^^^^^^^^^^^^^^^^^
  File "d:\mesdocuments\paul\gertrude\travail\R&D\projets\generation_diag\travail\src\FpfEnv_v2.py", line 164, in _compute_observations
    "action_mask" : agent.compute_action_mask()
                    ^^^^^^^^^^^^^^^^^^^^^^^^^^^
  File "d:\mesdocuments\paul\gertrude\travail\R&D\projets\generation_diag\travail\src\Feu.py", line 121, in compute_action_mask
    raise Exception(f"Impossible d'avoir plus de 3 sec de orange.\nself.consecutive_durations : {self.consecutive_durations['y']}")
Exception: Impossible d'avoir plus de 3 sec de orange.
self.consecutive_durations : 4
